Traceback (most recent call last):
  File "/home/p_gnngw/miniconda3/envs/cuda118/lib/python3.12/site-packages/dgl/graphbolt/__init__.py", line 50, in load_graphbolt
    torch.classes.load_library(path)
  File "/home/p_gnngw/miniconda3/envs/cuda118/lib/python3.12/site-packages/torch/_classes.py", line 51, in load_library
    torch.ops.load_library(path)
  File "/home/p_gnngw/miniconda3/envs/cuda118/lib/python3.12/site-packages/torch/_ops.py", line 933, in load_library
    ctypes.CDLL(path)
  File "/home/p_gnngw/miniconda3/envs/cuda118/lib/python3.12/ctypes/__init__.py", line 379, in __init__
    self._handle = _dlopen(self._name, mode)
                   ^^^^^^^^^^^^^^^^^^^^^^^^^
OSError: libcuda.so.1: cannot open shared object file: No such file or directory

During handling of the above exception, another exception occurred:

Traceback (most recent call last):
  File "/project/p_gnn001/code/tsp/tsp/test_save.py", line 18, in <module>
    from gnngls import algorithms, models, datasets
  File "/project/p_gnn001/code/tsp/tsp/gnngls/models.py", line 1, in <module>
    import dgl.nn
  File "/home/p_gnngw/miniconda3/envs/cuda118/lib/python3.12/site-packages/dgl/__init__.py", line 16, in <module>
    from . import (
  File "/home/p_gnngw/miniconda3/envs/cuda118/lib/python3.12/site-packages/dgl/dataloading/__init__.py", line 13, in <module>
    from .dataloader import *
  File "/home/p_gnngw/miniconda3/envs/cuda118/lib/python3.12/site-packages/dgl/dataloading/dataloader.py", line 27, in <module>
    from ..distributed import DistGraph
  File "/home/p_gnngw/miniconda3/envs/cuda118/lib/python3.12/site-packages/dgl/distributed/__init__.py", line 5, in <module>
    from .dist_graph import DistGraph, DistGraphServer, edge_split, node_split
  File "/home/p_gnngw/miniconda3/envs/cuda118/lib/python3.12/site-packages/dgl/distributed/dist_graph.py", line 11, in <module>
    from .. import backend as F, graphbolt as gb, heterograph_index
  File "/home/p_gnngw/miniconda3/envs/cuda118/lib/python3.12/site-packages/dgl/graphbolt/__init__.py", line 55, in <module>
    load_graphbolt()
  File "/home/p_gnngw/miniconda3/envs/cuda118/lib/python3.12/site-packages/dgl/graphbolt/__init__.py", line 52, in load_graphbolt
    raise ImportError("Cannot load Graphbolt C++ library")
ImportError: Cannot load Graphbolt C++ library
