device = cuda
Traceback (most recent call last):
  File "/project/p_gnn001/code/tsp/tsp/train2.py", line 323, in <module>
    main()
  File "/project/p_gnn001/code/tsp/tsp/train2.py", line 316, in main
    val_loss = run(args)
               ^^^^^^^^^
  File "/project/p_gnn001/code/tsp/tsp/train2.py", line 165, in run
    _, feat_dim = train_set[0].ndata['weight'].shape
                  ~~~~~~~~~^^^
  File "/project/p_gnn001/code/tsp/tsp/gnngls/datasets.py", line 157, in __getitem__
    H = self.get_scaled_features(G)
        ^^^^^^^^^^^^^^^^^^^^^^^^^^^
  File "/project/p_gnn001/code/tsp/tsp/gnngls/datasets.py", line 179, in get_scaled_features
    H.ndata['e'] = self.G.ndata['e']
                   ~~~~~~~~~~~~^^^^^
  File "/home/p_gnngw/miniconda3/envs/cuda118/lib/python3.12/site-packages/dgl/view.py", line 80, in __getitem__
    return self._graph._get_n_repr(self._ntid, self._nodes)[key]
           ~~~~~~~~~~~~~~~~~~~~~~~~~~~~~~~~~~~~~~~~~~~~~~~~^^^^^
  File "/home/p_gnngw/miniconda3/envs/cuda118/lib/python3.12/site-packages/dgl/frame.py", line 688, in __getitem__
    return self._columns[name].data
           ~~~~~~~~~~~~~^^^^^^
KeyError: 'e'
